[2021-03-12 04:09:02,553] {taskinstance.py:851} INFO - Dependencies all met for <TaskInstance: conversion_flow.taskPrepare 2021-03-12T04:09:01+00:00 [queued]>
[2021-03-12 04:09:02,561] {taskinstance.py:851} INFO - Dependencies all met for <TaskInstance: conversion_flow.taskPrepare 2021-03-12T04:09:01+00:00 [queued]>
[2021-03-12 04:09:02,561] {taskinstance.py:1042} INFO - 
--------------------------------------------------------------------------------
[2021-03-12 04:09:02,562] {taskinstance.py:1043} INFO - Starting attempt 1 of 1
[2021-03-12 04:09:02,562] {taskinstance.py:1044} INFO - 
--------------------------------------------------------------------------------
[2021-03-12 04:09:02,567] {taskinstance.py:1063} INFO - Executing <Task(PythonOperator): taskPrepare> on 2021-03-12T04:09:01+00:00
[2021-03-12 04:09:02,569] {standard_task_runner.py:52} INFO - Started process 1500 to run task
[2021-03-12 04:09:02,571] {standard_task_runner.py:76} INFO - Running: ['airflow', 'tasks', 'run', 'conversion_flow', 'taskPrepare', '2021-03-12T04:09:01+00:00', '--job-id', '3', '--pool', 'default_pool', '--raw', '--subdir', '/srv/app/src/ckanext-mysql2mongodb/ckanext/mysql2mongodb/data_conv/dag/conversion_flow.py', '--cfg-path', '/tmp/tmp3vht65br', '--error-file', '/tmp/tmp5qvwkj1l']
[2021-03-12 04:09:02,572] {standard_task_runner.py:77} INFO - Job 3: Subtask taskPrepare
[2021-03-12 04:09:02,595] {logging_mixin.py:104} INFO - Running <TaskInstance: conversion_flow.taskPrepare 2021-03-12T04:09:01+00:00 [running]> on host 83c843b036e0
[2021-03-12 04:09:02,616] {taskinstance.py:1257} INFO - Exporting the following env vars:
AIRFLOW_CTX_DAG_OWNER=airflow
AIRFLOW_CTX_DAG_ID=conversion_flow
AIRFLOW_CTX_TASK_ID=taskPrepare
AIRFLOW_CTX_EXECUTION_DATE=2021-03-12T04:09:01+00:00
AIRFLOW_CTX_DAG_RUN_ID=conversion_flow1615522141.537899
[2021-03-12 04:09:02,663] {logging_mixin.py:104} INFO - Connected to MySQL Server version  8.0.22
[2021-03-12 04:09:02,664] {conversion_flow.py:73} ERROR - Error Occure in taskPrepare Task!
[2021-03-12 04:09:02,664] {conversion_flow.py:74} ERROR - 1044 (42000): Access denied for user 'admin'@'%' to database 'sakila'
[2021-03-12 04:09:02,664] {taskinstance.py:1455} ERROR - 1044 (42000): Access denied for user 'admin'@'%' to database 'sakila'
Traceback (most recent call last):
  File "/usr/local/lib/python3.6/dist-packages/mysql/connector/connection_cext.py", line 506, in cmd_query
    raw_as_string=raw_as_string)
_mysql_connector.MySQLInterfaceError: Access denied for user 'admin'@'%' to database 'sakila'

During handling of the above exception, another exception occurred:

Traceback (most recent call last):
  File "/usr/local/lib/python3.6/dist-packages/airflow/models/taskinstance.py", line 1112, in _run_raw_task
    self._prepare_and_execute_task_with_callbacks(context, task)
  File "/usr/local/lib/python3.6/dist-packages/airflow/models/taskinstance.py", line 1285, in _prepare_and_execute_task_with_callbacks
    result = self._execute_task(context, task_copy)
  File "/usr/local/lib/python3.6/dist-packages/airflow/models/taskinstance.py", line 1315, in _execute_task
    result = task_copy.execute(context=context)
  File "/usr/local/lib/python3.6/dist-packages/airflow/operators/python.py", line 117, in execute
    return_value = self.execute_callable()
  File "/usr/local/lib/python3.6/dist-packages/airflow/operators/python.py", line 128, in execute_callable
    return self.python_callable(*self.op_args, **self.op_kwargs)
  File "/srv/app/src/ckanext-mysql2mongodb/ckanext/mysql2mongodb/data_conv/dag/conversion_flow.py", line 75, in taskPrepare
    raise exception
  File "/srv/app/src/ckanext-mysql2mongodb/ckanext/mysql2mongodb/data_conv/dag/conversion_flow.py", line 61, in taskPrepare
    mysql_cur.execute(f"CREATE DATABASE IF NOT EXISTS {mysql_dbname};")
  File "/usr/local/lib/python3.6/dist-packages/mysql/connector/cursor_cext.py", line 266, in execute
    raw_as_string=self._raw_as_string)
  File "/usr/local/lib/python3.6/dist-packages/mysql/connector/connection_cext.py", line 509, in cmd_query
    sqlstate=exc.sqlstate)
mysql.connector.errors.ProgrammingError: 1044 (42000): Access denied for user 'admin'@'%' to database 'sakila'
[2021-03-12 04:09:02,666] {taskinstance.py:1503} INFO - Marking task as FAILED. dag_id=conversion_flow, task_id=taskPrepare, execution_date=20210312T040901, start_date=20210312T040902, end_date=20210312T040902
[2021-03-12 04:09:02,703] {local_task_job.py:146} INFO - Task exited with return code 1
