[2021-03-12 07:56:36,590] {taskinstance.py:851} INFO - Dependencies all met for <TaskInstance: conversion_flow.taskUploadResult 2021-03-12T07:56:03+00:00 [queued]>
[2021-03-12 07:56:36,601] {taskinstance.py:851} INFO - Dependencies all met for <TaskInstance: conversion_flow.taskUploadResult 2021-03-12T07:56:03+00:00 [queued]>
[2021-03-12 07:56:36,601] {taskinstance.py:1042} INFO - 
--------------------------------------------------------------------------------
[2021-03-12 07:56:36,601] {taskinstance.py:1043} INFO - Starting attempt 1 of 1
[2021-03-12 07:56:36,601] {taskinstance.py:1044} INFO - 
--------------------------------------------------------------------------------
[2021-03-12 07:56:36,611] {taskinstance.py:1063} INFO - Executing <Task(PythonOperator): taskUploadResult> on 2021-03-12T07:56:03+00:00
[2021-03-12 07:56:36,613] {standard_task_runner.py:52} INFO - Started process 724 to run task
[2021-03-12 07:56:36,616] {standard_task_runner.py:76} INFO - Running: ['airflow', 'tasks', 'run', 'conversion_flow', 'taskUploadResult', '2021-03-12T07:56:03+00:00', '--job-id', '30', '--pool', 'default_pool', '--raw', '--subdir', '/srv/app/src/ckanext-mysql2mongodb/ckanext/mysql2mongodb/data_conv/dag/conversion_flow.py', '--cfg-path', '/tmp/tmpugslfe1s', '--error-file', '/tmp/tmplcu60pq5']
[2021-03-12 07:56:36,617] {standard_task_runner.py:77} INFO - Job 30: Subtask taskUploadResult
[2021-03-12 07:56:36,647] {logging_mixin.py:104} INFO - Running <TaskInstance: conversion_flow.taskUploadResult 2021-03-12T07:56:03+00:00 [running]> on host 83c843b036e0
[2021-03-12 07:56:36,675] {taskinstance.py:1257} INFO - Exporting the following env vars:
AIRFLOW_CTX_DAG_OWNER=airflow
AIRFLOW_CTX_DAG_ID=conversion_flow
AIRFLOW_CTX_TASK_ID=taskUploadResult
AIRFLOW_CTX_EXECUTION_DATE=2021-03-12T07:56:03+00:00
AIRFLOW_CTX_DAG_RUN_ID=conversion_flow1615535763.509049
[2021-03-12 07:56:36,730] {conversion_flow.py:194} ERROR - Error Occure in taskUploadResult Task!
[2021-03-12 07:56:36,731] {conversion_flow.py:195} ERROR - [Errno 2] No such file or directory: './mongodump_files/sakila.zip'
[2021-03-12 07:56:36,731] {taskinstance.py:1455} ERROR - [Errno 2] No such file or directory: './mongodump_files/sakila.zip'
Traceback (most recent call last):
  File "/usr/local/lib/python3.6/dist-packages/airflow/models/taskinstance.py", line 1112, in _run_raw_task
    self._prepare_and_execute_task_with_callbacks(context, task)
  File "/usr/local/lib/python3.6/dist-packages/airflow/models/taskinstance.py", line 1285, in _prepare_and_execute_task_with_callbacks
    result = self._execute_task(context, task_copy)
  File "/usr/local/lib/python3.6/dist-packages/airflow/models/taskinstance.py", line 1315, in _execute_task
    result = task_copy.execute(context=context)
  File "/usr/local/lib/python3.6/dist-packages/airflow/operators/python.py", line 117, in execute
    return_value = self.execute_callable()
  File "/usr/local/lib/python3.6/dist-packages/airflow/operators/python.py", line 128, in execute_callable
    return self.python_callable(*self.op_args, **self.op_kwargs)
  File "/srv/app/src/ckanext-mysql2mongodb/ckanext/mysql2mongodb/data_conv/dag/conversion_flow.py", line 196, in taskUploadResult
    raise exception
  File "/srv/app/src/ckanext-mysql2mongodb/ckanext/mysql2mongodb/data_conv/dag/conversion_flow.py", line 191, in taskUploadResult
    files={'upload': open(f"./mongodump_files/{schema_name}.zip", 'rb')})
FileNotFoundError: [Errno 2] No such file or directory: './mongodump_files/sakila.zip'
[2021-03-12 07:56:36,732] {taskinstance.py:1503} INFO - Marking task as FAILED. dag_id=conversion_flow, task_id=taskUploadResult, execution_date=20210312T075603, start_date=20210312T075636, end_date=20210312T075636
[2021-03-12 07:56:36,749] {local_task_job.py:146} INFO - Task exited with return code 1
