[2021-03-12 07:52:21,497] {taskinstance.py:851} INFO - Dependencies all met for <TaskInstance: conversion_flow.taskSchemaConv 2021-03-12T07:52:17+00:00 [queued]>
[2021-03-12 07:52:21,505] {taskinstance.py:851} INFO - Dependencies all met for <TaskInstance: conversion_flow.taskSchemaConv 2021-03-12T07:52:17+00:00 [queued]>
[2021-03-12 07:52:21,506] {taskinstance.py:1042} INFO - 
--------------------------------------------------------------------------------
[2021-03-12 07:52:21,506] {taskinstance.py:1043} INFO - Starting attempt 1 of 1
[2021-03-12 07:52:21,506] {taskinstance.py:1044} INFO - 
--------------------------------------------------------------------------------
[2021-03-12 07:52:21,510] {taskinstance.py:1063} INFO - Executing <Task(PythonOperator): taskSchemaConv> on 2021-03-12T07:52:17+00:00
[2021-03-12 07:52:21,512] {standard_task_runner.py:52} INFO - Started process 177 to run task
[2021-03-12 07:52:21,514] {standard_task_runner.py:76} INFO - Running: ['airflow', 'tasks', 'run', 'conversion_flow', 'taskSchemaConv', '2021-03-12T07:52:17+00:00', '--job-id', '25', '--pool', 'default_pool', '--raw', '--subdir', '/srv/app/src/ckanext-mysql2mongodb/ckanext/mysql2mongodb/data_conv/dag/conversion_flow.py', '--cfg-path', '/tmp/tmpw2twbkmo', '--error-file', '/tmp/tmp81bu0v64']
[2021-03-12 07:52:21,515] {standard_task_runner.py:77} INFO - Job 25: Subtask taskSchemaConv
[2021-03-12 07:52:21,538] {logging_mixin.py:104} INFO - Running <TaskInstance: conversion_flow.taskSchemaConv 2021-03-12T07:52:17+00:00 [running]> on host 83c843b036e0
[2021-03-12 07:52:21,560] {taskinstance.py:1257} INFO - Exporting the following env vars:
AIRFLOW_CTX_DAG_OWNER=airflow
AIRFLOW_CTX_DAG_ID=conversion_flow
AIRFLOW_CTX_TASK_ID=taskSchemaConv
AIRFLOW_CTX_EXECUTION_DATE=2021-03-12T07:52:17+00:00
AIRFLOW_CTX_DAG_RUN_ID=conversion_flow1615535537.345794
[2021-03-12 07:52:24,486] {logging_mixin.py:104} INFO - Generate MySQL database sakila successfully!
[2021-03-12 07:52:24,517] {logging_mixin.py:104} INFO - Save schema from sakila database to MongoDB successfully!
[2021-03-12 07:52:24,536] {conversion_flow.py:113} ERROR - Error Occure in taskDataConv Task!
[2021-03-12 07:52:24,536] {conversion_flow.py:114} ERROR - open_connection_mongodb() takes 1 positional argument but 3 were given
[2021-03-12 07:52:24,536] {taskinstance.py:1455} ERROR - open_connection_mongodb() takes 1 positional argument but 3 were given
Traceback (most recent call last):
  File "/usr/local/lib/python3.6/dist-packages/airflow/models/taskinstance.py", line 1112, in _run_raw_task
    self._prepare_and_execute_task_with_callbacks(context, task)
  File "/usr/local/lib/python3.6/dist-packages/airflow/models/taskinstance.py", line 1285, in _prepare_and_execute_task_with_callbacks
    result = self._execute_task(context, task_copy)
  File "/usr/local/lib/python3.6/dist-packages/airflow/models/taskinstance.py", line 1315, in _execute_task
    result = task_copy.execute(context=context)
  File "/usr/local/lib/python3.6/dist-packages/airflow/operators/python.py", line 117, in execute
    return_value = self.execute_callable()
  File "/usr/local/lib/python3.6/dist-packages/airflow/operators/python.py", line 128, in execute_callable
    return self.python_callable(*self.op_args, **self.op_kwargs)
  File "/srv/app/src/ckanext-mysql2mongodb/ckanext/mysql2mongodb/data_conv/dag/conversion_flow.py", line 115, in taskSchemaConv
    raise exception
  File "/srv/app/src/ckanext-mysql2mongodb/ckanext/mysql2mongodb/data_conv/dag/conversion_flow.py", line 103, in taskSchemaConv
    schema_conversion.run()
  File "/srv/app/src/ckanext-mysql2mongodb/ckanext/mysql2mongodb/data_conv/schema_conversion.py", line 38, in run
    self.save_schema_view()
  File "/srv/app/src/ckanext-mysql2mongodb/ckanext/mysql2mongodb/data_conv/schema_conversion.py", line 522, in save_schema_view
    mongodb_connection = open_connection_mongodb(self.schema_conv_output_option.host, self.schema_conv_output_option.port, self.schema_conv_output_option.dbname)
TypeError: open_connection_mongodb() takes 1 positional argument but 3 were given
[2021-03-12 07:52:24,537] {taskinstance.py:1503} INFO - Marking task as FAILED. dag_id=conversion_flow, task_id=taskSchemaConv, execution_date=20210312T075217, start_date=20210312T075221, end_date=20210312T075224
[2021-03-12 07:52:24,581] {local_task_job.py:146} INFO - Task exited with return code 1
